<mujoco model="water_tank">
    <include file="../../common.xml"/>
    <worldbody>
        <body name="object_entity" pos="0.0 0.0 0.06">
            <joint name="OBJTx" pos="0 0 0" axis="1 0 0" type="slide" class="freejoint" />
            <joint name="OBJTy" pos="0 0 0" axis="0 1 0" type="slide" class="freejoint" />
            <joint name="OBJTz" pos="0 0 0" axis="0 0 1" type="slide" class="freejoint" />
            <joint name="OBJRx" pos="0 0 0" axis="1 0 0" class="freejoint" />
            <joint name="OBJRy" pos="0 0 0" axis="0 1 0" class="freejoint" />
            <joint name="OBJRz" pos="0 0 0" axis="0 0 1" class="freejoint" />
            <geom type="box" name="entity_visual0" class="object_visual" pos="0 0 0.006" size="0.063 0.063 0.006" rgba="0.3 0.3 0.3 1" />
            <geom type="box" name="entity_contact0" class="object_contact" pos="0 0 0.006" size="0.075 0.075 0.024" mass="0.5" />
            <geom type="box" name="entity_visual1" class="object_visual" pos="0.06899999999999999 0 0.03" size="0.006 0.075 0.03" rgba="0.3 0.3 0.3 1" />
            <geom type="box" name="entity_contact1" class="object_contact" pos="0.06899999999999999 0 0.03" size="0.024 0.075 0.03" mass="0.5" />
            <geom type="box" name="entity_visual2" class="object_visual" pos="0 0.06899999999999999 0.03" size="0.063 0.006 0.03" rgba="0.3 0.3 0.3 1" />
            <geom type="box" name="entity_contact2" class="object_contact" pos="0 0.06899999999999999 0.03" size="0.075 0.024 0.03" mass="0.5" />
            <geom type="box" name="entity_visual3" class="object_visual" pos="-0.06899999999999999 0 0.03" size="0.006 0.075 0.03" rgba="0.3 0.3 0.3 1" />
            <geom type="box" name="entity_contact3" class="object_contact" pos="-0.06899999999999999 0 0.03" size="0.024 0.075 0.03" mass="0.5" />
            <geom type="box" name="entity_visual4" class="object_visual" pos="0 -0.06899999999999999 0.03" size="0.063 0.006 0.03" rgba="0.3 0.3 0.3 1" />
            <geom type="box" name="entity_contact4" class="object_contact" pos="0 -0.06899999999999999 0.03" size="0.075 0.024 0.03" mass="0.5" />
        </body>
    </worldbody>
</mujoco>