<mujoco model="025_mug">
    <include file="../../common.xml"/>
    <asset>
        <mesh name="025_mug" file="../../ycb/025_mug/textured.obj"  />
	<mesh name="contact0" file="../../ycb/025_mug/contact0.stl"  />
	<mesh name="contact1" file="../../ycb/025_mug/contact1.stl"  />
	<mesh name="contact2" file="../../ycb/025_mug/contact2.stl"  />
	<mesh name="contact3" file="../../ycb/025_mug/contact3.stl"  />
	<mesh name="contact4" file="../../ycb/025_mug/contact4.stl"  />
	<mesh name="contact5" file="../../ycb/025_mug/contact5.stl"  />
	<mesh name="contact6" file="../../ycb/025_mug/contact6.stl"  />
	<mesh name="contact7" file="../../ycb/025_mug/contact7.stl"  />
	<mesh name="contact8" file="../../ycb/025_mug/contact8.stl"  />
	<mesh name="contact9" file="../../ycb/025_mug/contact9.stl"  />
	<mesh name="contact10" file="../../ycb/025_mug/contact10.stl"  />
	<mesh name="contact11" file="../../ycb/025_mug/contact11.stl"  />
	<mesh name="contact12" file="../../ycb/025_mug/contact12.stl"  />
	<mesh name="contact13" file="../../ycb/025_mug/contact13.stl"  />
	<mesh name="contact14" file="../../ycb/025_mug/contact14.stl"  />
	<mesh name="contact15" file="../../ycb/025_mug/contact15.stl"  />
    </asset>
    <worldbody>
        <body name="object_entity" pos="0.0 0.0 0.0198">
            <joint name="OBJTx" pos="0 0 0" axis="1 0 0" type="slide" class="freejoint" />
            <joint name="OBJTy" pos="0 0 0" axis="0 1 0" type="slide" class="freejoint" />
            <joint name="OBJTz" pos="0 0 0" axis="0 0 1" type="slide" class="freejoint" />
            <joint name="OBJRx" pos="0 0 0" axis="1 0 0" class="freejoint" />
            <joint name="OBJRy" pos="0 0 0" axis="0 1 0" class="freejoint" />
            <joint name="OBJRz" pos="0 0 0" axis="0 0 1" class="freejoint" />
            <geom name="entity_visual" class="object_visual" mesh="025_mug" />
	    <geom name="entity_contact0" class="object_contact" mesh="contact0" />
	    <geom name="entity_contact1" class="object_contact" mesh="contact1" />
	    <geom name="entity_contact2" class="object_contact" mesh="contact2" />
	    <geom name="entity_contact3" class="object_contact" mesh="contact3" />
	    <geom name="entity_contact4" class="object_contact" mesh="contact4" />
	    <geom name="entity_contact5" class="object_contact" mesh="contact5" />
	    <geom name="entity_contact6" class="object_contact" mesh="contact6" />
	    <geom name="entity_contact7" class="object_contact" mesh="contact7" />
	    <geom name="entity_contact8" class="object_contact" mesh="contact8" />
	    <geom name="entity_contact9" class="object_contact" mesh="contact9" />
	    <geom name="entity_contact10" class="object_contact" mesh="contact10" />
	    <geom name="entity_contact11" class="object_contact" mesh="contact11" />
	    <geom name="entity_contact12" class="object_contact" mesh="contact12" />
	    <geom name="entity_contact13" class="object_contact" mesh="contact13" />
	    <geom name="entity_contact14" class="object_contact" mesh="contact14" />
	    <geom name="entity_contact15" class="object_contact" mesh="contact15" />
	    <composite type="particle" count="2 2 3" spacing="0.012" offset="0.0 0.0 0.02">
	    	<joint kind="main" damping="0.01"/>
	    	<geom size="0.01" rgba="0.3216 0.3569 0.9804 0.6" condim="3"/>
	    </composite>
        </body>
    </worldbody>
</mujoco>
