<mujoco model="005_tomato_soup_can">
    <include file="../../common.xml"/>
    <asset>
        <mesh name="005_tomato_soup_can" file="../../ycb/005_tomato_soup_can/textured.obj"  />
        <mesh name="contact0" file="../../ycb/005_tomato_soup_can/contact0.stl"  />
    </asset>
    <worldbody>
        <body name="object_entity" pos="0.0 0.0 0.0244">
            <joint name="OBJTx" pos="0 0 0" axis="1 0 0" type="slide" class="freejoint" />
            <joint name="OBJTy" pos="0 0 0" axis="0 1 0" type="slide" class="freejoint" />
            <joint name="OBJTz" pos="0 0 0" axis="0 0 1" type="slide" class="freejoint" />
            <joint name="OBJRx" pos="0 0 0" axis="1 0 0" class="freejoint" />
            <joint name="OBJRy" pos="0 0 0" axis="0 1 0" class="freejoint" />
            <joint name="OBJRz" pos="0 0 0" axis="0 0 1" class="freejoint" />
            <geom name="entity_visual" class="object_visual" mesh="005_tomato_soup_can" />
            <geom name="entity_contact0" class="object_contact" mesh="contact0" />
        </body>
    </worldbody>
</mujoco>
