<mujoco model="007_tuna_fish_can">
    <include file="../../common.xml"/>
    <asset>
        <mesh name="007_tuna_fish_can" file="../../ycb/007_tuna_fish_can/textured.obj"  />
        <mesh name="contact0" file="../../ycb/007_tuna_fish_can/contact0.stl"  />
        <mesh name="contact1" file="../../ycb/007_tuna_fish_can/contact1.stl"  />
        <mesh name="contact2" file="../../ycb/007_tuna_fish_can/contact2.stl"  />
        <mesh name="contact3" file="../../ycb/007_tuna_fish_can/contact3.stl"  />
        <mesh name="contact4" file="../../ycb/007_tuna_fish_can/contact4.stl"  />
        <mesh name="contact5" file="../../ycb/007_tuna_fish_can/contact5.stl"  />
        <mesh name="contact6" file="../../ycb/007_tuna_fish_can/contact6.stl"  />
        <mesh name="contact7" file="../../ycb/007_tuna_fish_can/contact7.stl"  />
        <mesh name="contact8" file="../../ycb/007_tuna_fish_can/contact8.stl"  />
        <mesh name="contact9" file="../../ycb/007_tuna_fish_can/contact9.stl"  />
        <mesh name="contact10" file="../../ycb/007_tuna_fish_can/contact10.stl"  />
        <mesh name="contact11" file="../../ycb/007_tuna_fish_can/contact11.stl"  />
        <mesh name="contact12" file="../../ycb/007_tuna_fish_can/contact12.stl"  />
        <mesh name="contact13" file="../../ycb/007_tuna_fish_can/contact13.stl"  />
        <mesh name="contact14" file="../../ycb/007_tuna_fish_can/contact14.stl"  />
        <mesh name="contact15" file="../../ycb/007_tuna_fish_can/contact15.stl"  />
    </asset>
    <worldbody>
        <body name="object_entity" pos="0.0 0.0 -0.0084">
            <joint name="OBJTx" pos="0 0 0" axis="1 0 0" type="slide" class="freejoint" />
            <joint name="OBJTy" pos="0 0 0" axis="0 1 0" type="slide" class="freejoint" />
            <joint name="OBJTz" pos="0 0 0" axis="0 0 1" type="slide" class="freejoint" />
            <joint name="OBJRx" pos="0 0 0" axis="1 0 0" class="freejoint" />
            <joint name="OBJRy" pos="0 0 0" axis="0 1 0" class="freejoint" />
            <joint name="OBJRz" pos="0 0 0" axis="0 0 1" class="freejoint" />
            <geom name="entity_visual" class="object_visual" mesh="007_tuna_fish_can" />
            <geom name="entity_contact0" class="object_contact" mesh="contact0" />
            <geom name="entity_contact1" class="object_contact" mesh="contact1" />
            <geom name="entity_contact2" class="object_contact" mesh="contact2" />
            <geom name="entity_contact3" class="object_contact" mesh="contact3" />
            <geom name="entity_contact4" class="object_contact" mesh="contact4" />
            <geom name="entity_contact5" class="object_contact" mesh="contact5" />
            <geom name="entity_contact6" class="object_contact" mesh="contact6" />
            <geom name="entity_contact7" class="object_contact" mesh="contact7" />
            <geom name="entity_contact8" class="object_contact" mesh="contact8" />
            <geom name="entity_contact9" class="object_contact" mesh="contact9" />
            <geom name="entity_contact10" class="object_contact" mesh="contact10" />
            <geom name="entity_contact11" class="object_contact" mesh="contact11" />
            <geom name="entity_contact12" class="object_contact" mesh="contact12" />
            <geom name="entity_contact13" class="object_contact" mesh="contact13" />
            <geom name="entity_contact14" class="object_contact" mesh="contact14" />
            <geom name="entity_contact15" class="object_contact" mesh="contact15" />
        </body>
    </worldbody>
</mujoco>