<mujoco model="009_gelatin_box">
    <include file="../../common.xml"/>
    <asset>
        <mesh name="009_gelatin_box" file="../../ycb/009_gelatin_box/textured.obj"  />
        <mesh name="contact0" file="../../ycb/009_gelatin_box/contact0.stl"  />
        <mesh name="contact1" file="../../ycb/009_gelatin_box/contact1.stl"  />
    </asset>
    <worldbody>
        <body name="009_gelatin_box" pos="0.0 0.0 -0.0093">
            <joint name="OBJTx" pos="0 0 0" axis="1 0 0" type="slide" class="freejoint" />
            <joint name="OBJTy" pos="0 0 0" axis="0 1 0" type="slide" class="freejoint" />
            <joint name="OBJTz" pos="0 0 0" axis="0 0 1" type="slide" class="freejoint" />
            <joint name="OBJRx" pos="0 0 0" axis="1 0 0" class="freejoint" />
            <joint name="OBJRy" pos="0 0 0" axis="0 1 0" class="freejoint" />
            <joint name="OBJRz" pos="0 0 0" axis="0 0 1" class="freejoint" />
            <geom name="009_gelatin_box_visual" class="object_visual" mesh="009_gelatin_box" />
            <geom name="009_gelatin_box_contact0" class="object_contact" mesh="contact0" />
            <geom name="009_gelatin_box_contact1" class="object_contact" mesh="contact1" />
        </body>
    </worldbody>
</mujoco>