<mujoco model="019_pitcher_base">
    <include file="../../common.xml"/>
    <asset>
        <mesh name="019_pitcher_base" file="../../ycb/019_pitcher_base/textured.obj"  />
        <mesh name="contact0" file="../../ycb/019_pitcher_base/contact0.stl"  />
        <mesh name="contact1" file="../../ycb/019_pitcher_base/contact1.stl"  />
        <mesh name="contact2" file="../../ycb/019_pitcher_base/contact2.stl"  />
        <mesh name="contact3" file="../../ycb/019_pitcher_base/contact3.stl"  />
        <mesh name="contact4" file="../../ycb/019_pitcher_base/contact4.stl"  />
        <mesh name="contact5" file="../../ycb/019_pitcher_base/contact5.stl"  />
        <mesh name="contact6" file="../../ycb/019_pitcher_base/contact6.stl"  />
        <mesh name="contact7" file="../../ycb/019_pitcher_base/contact7.stl"  />
        <mesh name="contact8" file="../../ycb/019_pitcher_base/contact8.stl"  />
        <mesh name="contact9" file="../../ycb/019_pitcher_base/contact9.stl"  />
        <mesh name="contact10" file="../../ycb/019_pitcher_base/contact10.stl"  />
        <mesh name="contact11" file="../../ycb/019_pitcher_base/contact11.stl"  />
        <mesh name="contact12" file="../../ycb/019_pitcher_base/contact12.stl"  />
        <mesh name="contact13" file="../../ycb/019_pitcher_base/contact13.stl"  />
        <mesh name="contact14" file="../../ycb/019_pitcher_base/contact14.stl"  />
        <mesh name="contact15" file="../../ycb/019_pitcher_base/contact15.stl"  />
        <mesh name="contact16" file="../../ycb/019_pitcher_base/contact16.stl"  />
        <mesh name="contact17" file="../../ycb/019_pitcher_base/contact17.stl"  />
        <mesh name="contact18" file="../../ycb/019_pitcher_base/contact18.stl"  />
        <mesh name="contact19" file="../../ycb/019_pitcher_base/contact19.stl"  />
        <mesh name="contact20" file="../../ycb/019_pitcher_base/contact20.stl"  />
        <mesh name="contact21" file="../../ycb/019_pitcher_base/contact21.stl"  />
        <mesh name="contact22" file="../../ycb/019_pitcher_base/contact22.stl"  />
        <mesh name="contact23" file="../../ycb/019_pitcher_base/contact23.stl"  />
        <mesh name="contact24" file="../../ycb/019_pitcher_base/contact24.stl"  />
        <mesh name="contact25" file="../../ycb/019_pitcher_base/contact25.stl"  />
        <mesh name="contact26" file="../../ycb/019_pitcher_base/contact26.stl"  />
        <mesh name="contact27" file="../../ycb/019_pitcher_base/contact27.stl"  />
        <mesh name="contact28" file="../../ycb/019_pitcher_base/contact28.stl"  />
        <mesh name="contact29" file="../../ycb/019_pitcher_base/contact29.stl"  />
        <mesh name="contact30" file="../../ycb/019_pitcher_base/contact30.stl"  />
        <mesh name="contact31" file="../../ycb/019_pitcher_base/contact31.stl"  />
        <mesh name="contact32" file="../../ycb/019_pitcher_base/contact32.stl"  />
    </asset>
    <worldbody>
        <body name="019_pitcher_base" pos="0.0 0.0 0.1108">
            <joint name="OBJTx" pos="0 0 0" axis="1 0 0" type="slide" class="freejoint" />
            <joint name="OBJTy" pos="0 0 0" axis="0 1 0" type="slide" class="freejoint" />
            <joint name="OBJTz" pos="0 0 0" axis="0 0 1" type="slide" class="freejoint" />
            <joint name="OBJRx" pos="0 0 0" axis="1 0 0" class="freejoint" />
            <joint name="OBJRy" pos="0 0 0" axis="0 1 0" class="freejoint" />
            <joint name="OBJRz" pos="0 0 0" axis="0 0 1" class="freejoint" />
            <geom name="019_pitcher_base_visual" class="object_visual" mesh="019_pitcher_base" />
            <geom name="019_pitcher_base_contact0" class="object_contact" mesh="contact0" />
            <geom name="019_pitcher_base_contact1" class="object_contact" mesh="contact1" />
            <geom name="019_pitcher_base_contact2" class="object_contact" mesh="contact2" />
            <geom name="019_pitcher_base_contact3" class="object_contact" mesh="contact3" />
            <geom name="019_pitcher_base_contact4" class="object_contact" mesh="contact4" />
            <geom name="019_pitcher_base_contact5" class="object_contact" mesh="contact5" />
            <geom name="019_pitcher_base_contact6" class="object_contact" mesh="contact6" />
            <geom name="019_pitcher_base_contact7" class="object_contact" mesh="contact7" />
            <geom name="019_pitcher_base_contact8" class="object_contact" mesh="contact8" />
            <geom name="019_pitcher_base_contact9" class="object_contact" mesh="contact9" />
            <geom name="019_pitcher_base_contact10" class="object_contact" mesh="contact10" />
            <geom name="019_pitcher_base_contact11" class="object_contact" mesh="contact11" />
            <geom name="019_pitcher_base_contact12" class="object_contact" mesh="contact12" />
            <geom name="019_pitcher_base_contact13" class="object_contact" mesh="contact13" />
            <geom name="019_pitcher_base_contact14" class="object_contact" mesh="contact14" />
            <geom name="019_pitcher_base_contact15" class="object_contact" mesh="contact15" />
            <geom name="019_pitcher_base_contact16" class="object_contact" mesh="contact16" />
            <geom name="019_pitcher_base_contact17" class="object_contact" mesh="contact17" />
            <geom name="019_pitcher_base_contact18" class="object_contact" mesh="contact18" />
            <geom name="019_pitcher_base_contact19" class="object_contact" mesh="contact19" />
            <geom name="019_pitcher_base_contact20" class="object_contact" mesh="contact20" />
            <geom name="019_pitcher_base_contact21" class="object_contact" mesh="contact21" />
            <geom name="019_pitcher_base_contact22" class="object_contact" mesh="contact22" />
            <geom name="019_pitcher_base_contact23" class="object_contact" mesh="contact23" />
            <geom name="019_pitcher_base_contact24" class="object_contact" mesh="contact24" />
            <geom name="019_pitcher_base_contact25" class="object_contact" mesh="contact25" />
            <geom name="019_pitcher_base_contact26" class="object_contact" mesh="contact26" />
            <geom name="019_pitcher_base_contact27" class="object_contact" mesh="contact27" />
            <geom name="019_pitcher_base_contact28" class="object_contact" mesh="contact28" />
            <geom name="019_pitcher_base_contact29" class="object_contact" mesh="contact29" />
            <geom name="019_pitcher_base_contact30" class="object_contact" mesh="contact30" />
            <geom name="019_pitcher_base_contact31" class="object_contact" mesh="contact31" />
            <geom name="019_pitcher_base_contact32" class="object_contact" mesh="contact32" />
        </body>
    </worldbody>
</mujoco>