<mujoco model="024_bowl">
    <include file="../../common.xml"/>
    <asset>
        <mesh name="024_bowl" file="../../ycb/024_bowl/textured.obj"  />
        <mesh name="contact0" file="../../ycb/024_bowl/contact0.stl"  />
        <mesh name="contact1" file="../../ycb/024_bowl/contact1.stl"  />
        <mesh name="contact2" file="../../ycb/024_bowl/contact2.stl"  />
        <mesh name="contact3" file="../../ycb/024_bowl/contact3.stl"  />
        <mesh name="contact4" file="../../ycb/024_bowl/contact4.stl"  />
        <mesh name="contact5" file="../../ycb/024_bowl/contact5.stl"  />
        <mesh name="contact6" file="../../ycb/024_bowl/contact6.stl"  />
        <mesh name="contact7" file="../../ycb/024_bowl/contact7.stl"  />
        <mesh name="contact8" file="../../ycb/024_bowl/contact8.stl"  />
        <mesh name="contact9" file="../../ycb/024_bowl/contact9.stl"  />
        <mesh name="contact10" file="../../ycb/024_bowl/contact10.stl"  />
        <mesh name="contact11" file="../../ycb/024_bowl/contact11.stl"  />
        <mesh name="contact12" file="../../ycb/024_bowl/contact12.stl"  />
        <mesh name="contact13" file="../../ycb/024_bowl/contact13.stl"  />
        <mesh name="contact14" file="../../ycb/024_bowl/contact14.stl"  />
        <mesh name="contact15" file="../../ycb/024_bowl/contact15.stl"  />
        <mesh name="contact16" file="../../ycb/024_bowl/contact16.stl"  />
        <mesh name="contact17" file="../../ycb/024_bowl/contact17.stl"  />
        <mesh name="contact18" file="../../ycb/024_bowl/contact18.stl"  />
        <mesh name="contact19" file="../../ycb/024_bowl/contact19.stl"  />
        <mesh name="contact20" file="../../ycb/024_bowl/contact20.stl"  />
        <mesh name="contact21" file="../../ycb/024_bowl/contact21.stl"  />
        <mesh name="contact22" file="../../ycb/024_bowl/contact22.stl"  />
        <mesh name="contact23" file="../../ycb/024_bowl/contact23.stl"  />
        <mesh name="contact24" file="../../ycb/024_bowl/contact24.stl"  />
        <mesh name="contact25" file="../../ycb/024_bowl/contact25.stl"  />
        <mesh name="contact26" file="../../ycb/024_bowl/contact26.stl"  />
        <mesh name="contact27" file="../../ycb/024_bowl/contact27.stl"  />
        <mesh name="contact28" file="../../ycb/024_bowl/contact28.stl"  />
        <mesh name="contact29" file="../../ycb/024_bowl/contact29.stl"  />
        <mesh name="contact30" file="../../ycb/024_bowl/contact30.stl"  />
        <mesh name="contact31" file="../../ycb/024_bowl/contact31.stl"  />
        <mesh name="contact32" file="../../ycb/024_bowl/contact32.stl"  />
        <mesh name="contact33" file="../../ycb/024_bowl/contact33.stl"  />
        <mesh name="contact34" file="../../ycb/024_bowl/contact34.stl"  />
        <mesh name="contact35" file="../../ycb/024_bowl/contact35.stl"  />
        <mesh name="contact36" file="../../ycb/024_bowl/contact36.stl"  />
        <mesh name="contact37" file="../../ycb/024_bowl/contact37.stl"  />
        <mesh name="contact38" file="../../ycb/024_bowl/contact38.stl"  />
        <mesh name="contact39" file="../../ycb/024_bowl/contact39.stl"  />
    </asset>
    <worldbody>
        <body name="024_bowl" pos="0.0 0.0 0.0051">
            <joint name="OBJTx" pos="0 0 0" axis="1 0 0" type="slide" class="freejoint" />
            <joint name="OBJTy" pos="0 0 0" axis="0 1 0" type="slide" class="freejoint" />
            <joint name="OBJTz" pos="0 0 0" axis="0 0 1" type="slide" class="freejoint" />
            <joint name="OBJRx" pos="0 0 0" axis="1 0 0" class="freejoint" />
            <joint name="OBJRy" pos="0 0 0" axis="0 1 0" class="freejoint" />
            <joint name="OBJRz" pos="0 0 0" axis="0 0 1" class="freejoint" />
            <geom name="024_bowl_visual" class="object_visual" mesh="024_bowl" />
            <geom name="024_bowl_contact0" class="object_contact" mesh="contact0" />
            <geom name="024_bowl_contact1" class="object_contact" mesh="contact1" />
            <geom name="024_bowl_contact2" class="object_contact" mesh="contact2" />
            <geom name="024_bowl_contact3" class="object_contact" mesh="contact3" />
            <geom name="024_bowl_contact4" class="object_contact" mesh="contact4" />
            <geom name="024_bowl_contact5" class="object_contact" mesh="contact5" />
            <geom name="024_bowl_contact6" class="object_contact" mesh="contact6" />
            <geom name="024_bowl_contact7" class="object_contact" mesh="contact7" />
            <geom name="024_bowl_contact8" class="object_contact" mesh="contact8" />
            <geom name="024_bowl_contact9" class="object_contact" mesh="contact9" />
            <geom name="024_bowl_contact10" class="object_contact" mesh="contact10" />
            <geom name="024_bowl_contact11" class="object_contact" mesh="contact11" />
            <geom name="024_bowl_contact12" class="object_contact" mesh="contact12" />
            <geom name="024_bowl_contact13" class="object_contact" mesh="contact13" />
            <geom name="024_bowl_contact14" class="object_contact" mesh="contact14" />
            <geom name="024_bowl_contact15" class="object_contact" mesh="contact15" />
            <geom name="024_bowl_contact16" class="object_contact" mesh="contact16" />
            <geom name="024_bowl_contact17" class="object_contact" mesh="contact17" />
            <geom name="024_bowl_contact18" class="object_contact" mesh="contact18" />
            <geom name="024_bowl_contact19" class="object_contact" mesh="contact19" />
            <geom name="024_bowl_contact20" class="object_contact" mesh="contact20" />
            <geom name="024_bowl_contact21" class="object_contact" mesh="contact21" />
            <geom name="024_bowl_contact22" class="object_contact" mesh="contact22" />
            <geom name="024_bowl_contact23" class="object_contact" mesh="contact23" />
            <geom name="024_bowl_contact24" class="object_contact" mesh="contact24" />
            <geom name="024_bowl_contact25" class="object_contact" mesh="contact25" />
            <geom name="024_bowl_contact26" class="object_contact" mesh="contact26" />
            <geom name="024_bowl_contact27" class="object_contact" mesh="contact27" />
            <geom name="024_bowl_contact28" class="object_contact" mesh="contact28" />
            <geom name="024_bowl_contact29" class="object_contact" mesh="contact29" />
            <geom name="024_bowl_contact30" class="object_contact" mesh="contact30" />
            <geom name="024_bowl_contact31" class="object_contact" mesh="contact31" />
            <geom name="024_bowl_contact32" class="object_contact" mesh="contact32" />
            <geom name="024_bowl_contact33" class="object_contact" mesh="contact33" />
            <geom name="024_bowl_contact34" class="object_contact" mesh="contact34" />
            <geom name="024_bowl_contact35" class="object_contact" mesh="contact35" />
            <geom name="024_bowl_contact36" class="object_contact" mesh="contact36" />
            <geom name="024_bowl_contact37" class="object_contact" mesh="contact37" />
            <geom name="024_bowl_contact38" class="object_contact" mesh="contact38" />
            <geom name="024_bowl_contact39" class="object_contact" mesh="contact39" />
        </body>
    </worldbody>
</mujoco>