<mujoco model="037_scissors">
    <include file="../../common.xml"/>
    <asset>
        <mesh name="037_scissors" file="../../ycb/037_scissors/textured.obj"  />
        <mesh name="contact0" file="../../ycb/037_scissors/contact0.stl"  />
        <mesh name="contact1" file="../../ycb/037_scissors/contact1.stl"  />
        <mesh name="contact2" file="../../ycb/037_scissors/contact2.stl"  />
        <mesh name="contact3" file="../../ycb/037_scissors/contact3.stl"  />
        <mesh name="contact4" file="../../ycb/037_scissors/contact4.stl"  />
        <mesh name="contact5" file="../../ycb/037_scissors/contact5.stl"  />
        <mesh name="contact6" file="../../ycb/037_scissors/contact6.stl"  />
        <mesh name="contact7" file="../../ycb/037_scissors/contact7.stl"  />
        <mesh name="contact8" file="../../ycb/037_scissors/contact8.stl"  />
        <mesh name="contact9" file="../../ycb/037_scissors/contact9.stl"  />
        <mesh name="contact10" file="../../ycb/037_scissors/contact10.stl"  />
    </asset>
    <worldbody>
        <body name="object_entity" pos="0.0 0.0 -0.0171">
            <joint name="OBJTx" pos="0 0 0" axis="1 0 0" type="slide" class="freejoint" />
            <joint name="OBJTy" pos="0 0 0" axis="0 1 0" type="slide" class="freejoint" />
            <joint name="OBJTz" pos="0 0 0" axis="0 0 1" type="slide" class="freejoint" />
            <joint name="OBJRx" pos="0 0 0" axis="1 0 0" class="freejoint" />
            <joint name="OBJRy" pos="0 0 0" axis="0 1 0" class="freejoint" />
            <joint name="OBJRz" pos="0 0 0" axis="0 0 1" class="freejoint" />
            <geom name="entity_visual" class="object_visual" mesh="037_scissors" />
            <geom name="entity_contact0" class="object_contact" mesh="contact0" />
            <geom name="entity_contact1" class="object_contact" mesh="contact1" />
            <geom name="entity_contact2" class="object_contact" mesh="contact2" />
            <geom name="entity_contact3" class="object_contact" mesh="contact3" />
            <geom name="entity_contact4" class="object_contact" mesh="contact4" />
            <geom name="entity_contact5" class="object_contact" mesh="contact5" />
            <geom name="entity_contact6" class="object_contact" mesh="contact6" />
            <geom name="entity_contact7" class="object_contact" mesh="contact7" />
            <geom name="entity_contact8" class="object_contact" mesh="contact8" />
            <geom name="entity_contact9" class="object_contact" mesh="contact9" />
            <geom name="entity_contact10" class="object_contact" mesh="contact10" />
        </body>
    </worldbody>
</mujoco>