<mujoco model="040_large_marker">
    <include file="../../common.xml"/>
    <asset>
        <mesh name="040_large_marker" file="../../ycb/040_large_marker/textured.obj"  />
        <mesh name="contact0" file="../../ycb/040_large_marker/contact0.stl"  />
        <mesh name="contact1" file="../../ycb/040_large_marker/contact1.stl"  />
        <mesh name="contact2" file="../../ycb/040_large_marker/contact2.stl"  />
        <mesh name="contact3" file="../../ycb/040_large_marker/contact3.stl"  />
        <mesh name="contact4" file="../../ycb/040_large_marker/contact4.stl"  />
        <mesh name="contact5" file="../../ycb/040_large_marker/contact5.stl"  />
    </asset>
    <worldbody>
        <body name="040_large_marker" pos="0.0 0.0 -0.0154">
            <joint name="OBJTx" pos="0 0 0" axis="1 0 0" type="slide" class="freejoint" />
            <joint name="OBJTy" pos="0 0 0" axis="0 1 0" type="slide" class="freejoint" />
            <joint name="OBJTz" pos="0 0 0" axis="0 0 1" type="slide" class="freejoint" />
            <joint name="OBJRx" pos="0 0 0" axis="1 0 0" class="freejoint" />
            <joint name="OBJRy" pos="0 0 0" axis="0 1 0" class="freejoint" />
            <joint name="OBJRz" pos="0 0 0" axis="0 0 1" class="freejoint" />
            <geom name="040_large_marker_visual" class="object_visual" mesh="040_large_marker" />
            <geom name="040_large_marker_contact0" class="object_contact" mesh="contact0" />
            <geom name="040_large_marker_contact1" class="object_contact" mesh="contact1" />
            <geom name="040_large_marker_contact2" class="object_contact" mesh="contact2" />
            <geom name="040_large_marker_contact3" class="object_contact" mesh="contact3" />
            <geom name="040_large_marker_contact4" class="object_contact" mesh="contact4" />
            <geom name="040_large_marker_contact5" class="object_contact" mesh="contact5" />
        </body>
    </worldbody>
</mujoco>