<mujoco model="061_foam_brick">
    <include file="../../common.xml"/>
    <asset>
        <mesh name="061_foam_brick" file="../../ycb/061_foam_brick/textured.obj"  />
        <mesh name="contact0" file="../../ycb/061_foam_brick/contact0.stl"  />
        <mesh name="contact1" file="../../ycb/061_foam_brick/contact1.stl"  />
        <mesh name="contact2" file="../../ycb/061_foam_brick/contact2.stl"  />
        <mesh name="contact3" file="../../ycb/061_foam_brick/contact3.stl"  />
        <mesh name="contact4" file="../../ycb/061_foam_brick/contact4.stl"  />
        <mesh name="contact5" file="../../ycb/061_foam_brick/contact5.stl"  />
        <mesh name="contact6" file="../../ycb/061_foam_brick/contact6.stl"  />
        <mesh name="contact7" file="../../ycb/061_foam_brick/contact7.stl"  />
        <mesh name="contact8" file="../../ycb/061_foam_brick/contact8.stl"  />
        <mesh name="contact9" file="../../ycb/061_foam_brick/contact9.stl"  />
        <mesh name="contact10" file="../../ycb/061_foam_brick/contact10.stl"  />
        <mesh name="contact11" file="../../ycb/061_foam_brick/contact11.stl"  />
        <mesh name="contact12" file="../../ycb/061_foam_brick/contact12.stl"  />
        <mesh name="contact13" file="../../ycb/061_foam_brick/contact13.stl"  />
        <mesh name="contact14" file="../../ycb/061_foam_brick/contact14.stl"  />
        <mesh name="contact15" file="../../ycb/061_foam_brick/contact15.stl"  />
        <mesh name="contact16" file="../../ycb/061_foam_brick/contact16.stl"  />
        <mesh name="contact17" file="../../ycb/061_foam_brick/contact17.stl"  />
        <mesh name="contact18" file="../../ycb/061_foam_brick/contact18.stl"  />
        <mesh name="contact19" file="../../ycb/061_foam_brick/contact19.stl"  />
        <mesh name="contact20" file="../../ycb/061_foam_brick/contact20.stl"  />
        <mesh name="contact21" file="../../ycb/061_foam_brick/contact21.stl"  />
        <mesh name="contact22" file="../../ycb/061_foam_brick/contact22.stl"  />
        <mesh name="contact23" file="../../ycb/061_foam_brick/contact23.stl"  />
    </asset>
    <worldbody>
        <body name="object_entity" pos="0.0 0.0 -0.0002">
            <joint name="OBJTx" pos="0 0 0" axis="1 0 0" type="slide" class="freejoint" />
            <joint name="OBJTy" pos="0 0 0" axis="0 1 0" type="slide" class="freejoint" />
            <joint name="OBJTz" pos="0 0 0" axis="0 0 1" type="slide" class="freejoint" />
            <joint name="OBJRx" pos="0 0 0" axis="1 0 0" class="freejoint" />
            <joint name="OBJRy" pos="0 0 0" axis="0 1 0" class="freejoint" />
            <joint name="OBJRz" pos="0 0 0" axis="0 0 1" class="freejoint" />
            <geom name="entity_visual" class="object_visual" mesh="061_foam_brick" />
            <geom name="entity_contact0" class="object_contact" mesh="contact0" />
            <geom name="entity_contact1" class="object_contact" mesh="contact1" />
            <geom name="entity_contact2" class="object_contact" mesh="contact2" />
            <geom name="entity_contact3" class="object_contact" mesh="contact3" />
            <geom name="entity_contact4" class="object_contact" mesh="contact4" />
            <geom name="entity_contact5" class="object_contact" mesh="contact5" />
            <geom name="entity_contact6" class="object_contact" mesh="contact6" />
            <geom name="entity_contact7" class="object_contact" mesh="contact7" />
            <geom name="entity_contact8" class="object_contact" mesh="contact8" />
            <geom name="entity_contact9" class="object_contact" mesh="contact9" />
            <geom name="entity_contact10" class="object_contact" mesh="contact10" />
            <geom name="entity_contact11" class="object_contact" mesh="contact11" />
            <geom name="entity_contact12" class="object_contact" mesh="contact12" />
            <geom name="entity_contact13" class="object_contact" mesh="contact13" />
            <geom name="entity_contact14" class="object_contact" mesh="contact14" />
            <geom name="entity_contact15" class="object_contact" mesh="contact15" />
            <geom name="entity_contact16" class="object_contact" mesh="contact16" />
            <geom name="entity_contact17" class="object_contact" mesh="contact17" />
            <geom name="entity_contact18" class="object_contact" mesh="contact18" />
            <geom name="entity_contact19" class="object_contact" mesh="contact19" />
            <geom name="entity_contact20" class="object_contact" mesh="contact20" />
            <geom name="entity_contact21" class="object_contact" mesh="contact21" />
            <geom name="entity_contact22" class="object_contact" mesh="contact22" />
            <geom name="entity_contact23" class="object_contact" mesh="contact23" />
        </body>
    </worldbody>
</mujoco>